# 47. 에러 처리

## 47.1 에러 처리의 필요성

---

```jsx
console.log('[Start]');

try {
	foo();
} catch (error) {
	console.error('[에러 발생]'), error);
}
```

우리가 작성한 코드에서는 언제나 에러나 예외적인 상황이 발생할 수 있다는 것을 전제하고 이에 대응하는 코드를 작성하는 것이 중요

## 47.2 try catch finally 문

---

```jsx
console.log('[Start]');

try {
	foo();
} catch (error) {
	console.error('[에러 발생]'), error);
} finally {
	console.log('finally');
}
```

- try catch finally 문으로 에러를 처리하면 프로그램이 강제 종료되지 않음

## 47.3 Error 객체

---

**Error 객체**

- message 프로퍼티
  Error 생성자 함수에 인수로 전달한 에러 메시지
- stack 프로퍼티
  에러를 발생시킨 콜스택의 호출 정보를 나타내는 문자열

| 생성자 함수    | 인스턴스                                                         |
| -------------- | ---------------------------------------------------------------- |
| Error          | 일반적 에러 객체                                                 |
| SyntaxError    | 문법에 맞지 않는 문을 해석할 때 발생                             |
| ReferenceError | 참조할 수 없는 식별자를 참조했을 때 발생                         |
| TypeError      | 피연산자 또는 인수의 데이터 타입이 유효하지 않을 때 발생         |
| RangeError     | 숫자값의 허용 범위를 벗어났을 때 발생                            |
| URIError       | encodeURI 또는 decodeURI 함수에 부적절한 인수를 전달했을 때 발생 |
| EvalError      | eval 함수에서 발생                                               |

## 47.4 throw 문

---

```jsx
throw 표현식;
```

throw 문의 표현식은 어떤 값이라도 상관 없지만 **일반적으로 에러 객체를 지정**

## 47.5 에러의 전파

---

> 에러: 호출자 방향으로 전파됨

```jsx
const foo = () => {
  throw Error("foo에서 발생한 에러");
};

const bar = () => {
  foo();
};

const baz = () => {
  bar();
};

try {
  baz();
} catch (err) {
  console.error(err);
}
```

foo 함수가 throw한 에러: 호출자에게 전파되어 전역에서 캐치됨
